Workbook

Sheet Mapping
A1: Keyword | B1: Canonical Family
A2: PaaS and IaaS Universal Credits | B2: OCI
A3: Enterprise Performance Management | B3: EPM-Cloud
A4: Fusion Enterprise Resource Planning Cloud | B4: EPM-Cloud
A5: Hyperion | B5: Hyperion
A6: Essbase | B6: Essbase
A7: eBusiness Suite | B7: eBS
A8: Fusion HCM | B8: HCM-Cloud
A9: Recruiting
A10: Eloqua | B10: Eloqua
A11: Siebel | B11: Siebel
A12: RightNow | B12: RightNow
A13: Commerce Cloud | B13: Commerce-Cloud
A14: ATG Web Commerce | B14: ATG
A15: Endeca | B15: Endeca
A16: Real Application Clusters | B16: RAC
A17: Oracle Database | B17: Database
A18: WebLogic | B18: WebLogic
A19: Java SE | B19: Java
A20: Customer Hub
A21: Product Hub
A22: Procurement | B22: ERP-Cloud
A23: Supply Chain | B23: SCM
A24: Exadata Cloud at Customer | B24: ExaCC
A25: NEXUS | B25: Nexus
A26: ZFS | B26: ZFS
A27: Exadata | B27: Exadata
A28: PeopleSoft | B28: PSFT
A29: Primavera | B29: Primavera
A30: Database Appliance | B30: ODA
A31: AP 3900 | B31: TELCO-HW
A32: AP 1100 | B32: TELCO-HW
A33: WebCenter Content | B33: Webcenter
... A55: Oracle Communications Billing and Revenue Management Server for Billing | B55: TELCO-BRM

Sheet Products
A1: Product Name | B1: Canonical Family | D1: How to use | G1: {=_xlfn.UNIQUE(B:B)} -> Canonical Family
A2: Enterprise Data Management Cloud Service | B2: {=_xlfn.LET( _xlpm.p,A2, _xlpm.k,Mapping!$A$2:$A$55, _xlpm.f,Mapping!$B$2:$B$55, _xlpm.m,_xlfn.MAP(_xlpm.k,_xlfn.LAMBDA(_xlpm.x,ISNUMBER(SEARCH(_xlpm.x,_xlpm.p)))), IFERROR(INDEX(_xlpm.f,_xlfn.XMATCH(TRUE,_xlpm.m,0)),"Other") )} -> Other | D2: 1 | E2: Paste/import product names into column A. | G2: Other
A3: Oracle Enterprise Performance Management Enterprise Cloud Service | B3: {=_xlfn.LET( _xlpm.p,A3, _xlpm.k,Mapping!$A$2:$A$55, _xlpm.f,Mapping!$B$2:$B$55, _xlpm.m,_xlfn.MAP(_xlpm.k,_xlfn.LAMBDA(_xlpm.x,ISNUMBER(SEARCH(_xlpm.x,_xlpm.p)))), IFERROR(INDEX(_xlpm.f,_xlfn.XMATCH(TRUE,_xlpm.m,0)),"Other") )} -> EPM-Cloud | D3: 2 | E3: Column B maps each product using the Mapping tab. | G3: EPM-Cloud
A4: Fusion Enterprise Resource Planning Cloud Service | B4: {=_xlfn.LET( _xlpm.p,A4, _xlpm.k,Mapping!$A$2:$A$55, _xlpm.f,Mapping!$B$2:$B$55, _xlpm.m,_xlfn.MAP(_xlpm.k,_xlfn.LAMBDA(_xlpm.x,ISNUMBER(SEARCH(_xlpm.x,_xlpm.p)))), IFERROR(INDEX(_xlpm.f,_xlfn.XMATCH(TRUE,_xlpm.m,0)),"Other") )} -> EPM-Cloud | D4: 3 | E4: Add/edit keywords in Mapping as needed. | G4: OCI
A5: PaaS and IaaS Universal Credits | B5: {=_xlfn.LET( _xlpm.p,A5, _xlpm.k,Mapping!$A$2:$A$55, _xlpm.f,Mapping!$B$2:$B$55, _xlpm.m,_xlfn.MAP(_xlpm.k,_xlfn.LAMBDA(_xlpm.x,ISNUMBER(SEARCH(_xlpm.x,_xlpm.p)))), IFERROR(INDEX(_xlpm.f,_xlfn.XMATCH(TRUE,_xlpm.m,0)),"Other") )} -> OCI | D5: 4 | E5: Put specific keywords above broad keywords (first match wins). | G5: HCM-Cloud
A6: Fusion HCM Base | B6: {=_xlfn.LET( _xlpm.p,A6, _xlpm.k,Mapping!$A$2:$A$55, _xlpm.f,Mapping!$B$2:$B$55, _xlpm.m,_xlfn.MAP(_xlpm.k,_xlfn.LAMBDA(_xlpm.x,ISNUMBER(SEARCH(_xlpm.x,_xlpm.p)))), IFERROR(INDEX(_xlpm.f,_xlfn.XMATCH(TRUE,_xlpm.m,0)),"Other") )} -> HCM-Cloud | G6: ERP-Cloud
A7: Order Management - Usage | B7: {=_xlfn.LET( _xlpm.p,A7, _xlpm.k,Mapping!$A$2:$A$55, _xlpm.f,Mapping!$B$2:$B$55, _xlpm.m,_xlfn.MAP(_xlpm.k,_xlfn.LAMBDA(_xlpm.x,ISNUMBER(SEARCH(_xlpm.x,_xlpm.p)))), IFERROR(INDEX(_xlpm.f,_xlfn.XMATCH(TRUE,_xlpm.m,0)),"Other") )} -> Other | G7: SCM
A8: Procurement | B8: {=_xlfn.LET( _xlpm.p,A8, _xlpm.k,Mapping!$A$2:$A$55, _xlpm.f,Mapping!$B$2:$B$55, _xlpm.m,_xlfn.MAP(_xlpm.k,_xlfn.LAMBDA(_xlpm.x,ISNUMBER(SEARCH(_xlpm.x,_xlpm.p)))), IFERROR(INDEX(_xlpm.f,_xlfn.XMATCH(TRUE,_xlpm.m,0)),"Other") )} -> ERP-Cloud | G8: Hyperion
A9: Supply Chain Execution | B9: {=_xlfn.LET( _xlpm.p,A9, _xlpm.k,Mapping!$A$2:$A$55, _xlpm.f,Mapping!$B$2:$B$55, _xlpm.m,_xlfn.MAP(_xlpm.k,_xlfn.LAMBDA(_xlpm.x,ISNUMBER(SEARCH(_xlpm.x,_xlpm.p)))), IFERROR(INDEX(_xlpm.f,_xlfn.XMATCH(TRUE,_xlpm.m,0)),"Other") )} -> SCM | G9: Database
A10: PaaS and IaaS Universal Credits | B10: {=_xlfn.LET( _xlpm.p,A10, _xlpm.k,Mapping!$A$2:$A$55, _xlpm.f,Mapping!$B$2:$B$55, _xlpm.m,_xlfn.MAP(_xlpm.k,_xlfn.LAMBDA(_xlpm.x,ISNUMBER(SEARCH(_xlpm.x,_xlpm.p)))), IFERROR(INDEX(_xlpm.f,_xlfn.XMATCH(TRUE,_xlpm.m,0)),"Other") )} -> OCI | G10: TELCO-BRM
A11: Product Management Cloud Service | B11: {=_xlfn.LET( _xlpm.p,A11, _xlpm.k,Mapping!$A$2:$A$55, _xlpm.f,Mapping!$B$2:$B$55, _xlpm.m,_xlfn.MAP(_xlpm.k,_xlfn.LAMBDA(_xlpm.x,ISNUMBER(SEARCH(_xlpm.x,_xlpm.p)))), IFERROR(INDEX(_xlpm.f,_xlfn.XMATCH(TRUE,_xlpm.m,0)),"Other") )} -> Other | G11: RAC
A12: Fusion Talent Management Cloud Service | B12: {=_xlfn.LET( _xlpm.p,A12, _xlpm.k,Mapping!$A$2:$A$55, _xlpm.f,Mapping!$B$2:$B$55, _xlpm.m,_xlfn.MAP(_xlpm.k,_xlfn.LAMBDA(_xlpm.x,ISNUMBER(SEARCH(_xlpm.x,_xlpm.p)))), IFERROR(INDEX(_xlpm.f,_xlfn.XMATCH(TRUE,_xlpm.m,0)),"Other") )} -> Other | G12: TELCO-SW
A13: European Union Restricted Access Cloud Service for Oracle Fusion Applications | B13: {=_xlfn.LET( _xlpm.p,A13, _xlpm.k,Mapping!$A$2:$A$55, _xlpm.f,Mapping!$B$2:$B$55, _xlpm.m,_xlfn.MAP(_xlpm.k,_xlfn.LAMBDA(_xlpm.x,ISNUMBER(SEARCH(_xlpm.x,_xlpm.p)))), IFERROR(INDEX(_xlpm.f,_xlfn.XMATCH(TRUE,_xlpm.m,0)),"Other") )} -> Other | G13: TELCO-HW
A14: Fusion Workforce Compensation Cloud Service | B14: {=_xlfn.LET( _xlpm.p,A14, _xlpm.k,Mapping!$A$2:$A$55, _xlpm.f,Mapping!$B$2:$B$55, _xlpm.m,_xlfn.MAP(_xlpm.k,_xlfn.LAMBDA(_xlpm.x,ISNUMBER(SEARCH(_xlpm.x,_xlpm.p)))), IFERROR(INDEX(_xlpm.f,_xlfn.XMATCH(TRUE,_xlpm.m,0)),"Other") )} -> Other | G14: WebLogic
A15: Fusion Enterprise Resource Planning Cloud Service | B15: {=_xlfn.LET( _xlpm.p,A15, _xlpm.k,Mapping!$A$2:$A$55, _xlpm.f,Mapping!$B$2:$B$55, _xlpm.m,_xlfn.MAP(_xlpm.k,_xlfn.LAMBDA(_xlpm.x,ISNUMBER(SEARCH(_xlpm.x,_xlpm.p)))), IFERROR(INDEX(_xlpm.f,_xlfn.XMATCH(TRUE,_xlpm.m,0)),"Other") )} -> EPM-Cloud | G15: IAM
A16: Oracle Fusion Learning Management Cloud Service | B16: {=_xlfn.LET( _xlpm.p,A16, _xlpm.k,Mapping!$A$2:$A$55, _xlpm.f,Mapping!$B$2:$B$55, _xlpm.m,_xlfn.MAP(_xlpm.k,_xlfn.LAMBDA(_xlpm.x,ISNUMBER(SEARCH(_xlpm.x,_xlpm.p)))), IFERROR(INDEX(_xlpm.f,_xlfn.XMATCH(TRUE,_xlpm.m,0)),"Other") )} -> Other | G16: 0
A17: Order Management - Usage | B17: {=_xlfn.LET( _xlpm.p,A17, _xlpm.k,Mapping!$A$2:$A$55, _xlpm.f,Mapping!$B$2:$B$55, _xlpm.m,_xlfn.MAP(_xlpm.k,_xlfn.LAMBDA(_xlpm.x,ISNUMBER(SEARCH(_xlpm.x,_xlpm.p)))), IFERROR(INDEX(_xlpm.f,_xlfn.XMATCH(TRUE,_xlpm.m,0)),"Other") )} -> Other
A18: Oracle Additional Test Environment for Oracle Fusion Cloud Service | B18: {=_xlfn.LET( _xlpm.p,A18, _xlpm.k,Mapping!$A$2:$A$55, _xlpm.f,Mapping!$B$2:$B$55, _xlpm.m,_xlfn.MAP(_xlpm.k,_xlfn.LAMBDA(_xlpm.x,ISNUMBER(SEARCH(_xlpm.x,_xlpm.p)))), IFERROR(INDEX(_xlpm.f,_xlfn.XMATCH(TRUE,_xlpm.m,0)),"Other") )} -> Other
A19: Oracle Additional Test Environment for Oracle Fusion Cloud Service | B19: {=_xlfn.LET( _xlpm.p,A19, _xlpm.k,Mapping!$A$2:$A$55, _xlpm.f,Mapping!$B$2:$B$55, _xlpm.m,_xlfn.MAP(_xlpm.k,_xlfn.LAMBDA(_xlpm.x,ISNUMBER(SEARCH(_xlpm.x,_xlpm.p)))), IFERROR(INDEX(_xlpm.f,_xlfn.XMATCH(TRUE,_xlpm.m,0)),"Other") )} -> Other
A20: Oracle Additional Test Environment for Oracle Fusion Cloud Service | B20: {=_xlfn.LET( _xlpm.p,A20, _xlpm.k,Mapping!$A$2:$A$55, _xlpm.f,Mapping!$B$2:$B$55, _xlpm.m,_xlfn.MAP(_xlpm.k,_xlfn.LAMBDA(_xlpm.x,ISNUMBER(SEARCH(_xlpm.x,_xlpm.p)))), IFERROR(INDEX(_xlpm.f,_xlfn.XMATCH(TRUE,_xlpm.m,0)),"Other") )} -> Other
A21: Supply Chain Execution | B21: {=_xlfn.LET( _xlpm.p,A21, _xlpm.k,Mapping!$A$2:$A$55, _xlpm.f,Mapping!$B$2:$B$55, _xlpm.m,_xlfn.MAP(_xlpm.k,_xlfn.LAMBDA(_xlpm.x,ISNUMBER(SEARCH(_xlpm.x,_xlpm.p)))), IFERROR(INDEX(_xlpm.f,_xlfn.XMATCH(TRUE,_xlpm.m,0)),"Other") )} -> SCM
A22: Enterprise Data Management Cloud Service | B22: {=_xlfn.LET( _xlpm.p,A22, _xlpm.k,Mapping!$A$2:$A$55, _xlpm.f,Mapping!$B$2:$B$55, _xlpm.m,_xlfn.MAP(_xlpm.k,_xlfn.LAMBDA(_xlpm.x,ISNUMBER(SEARCH(_xlpm.x,_xlpm.p)))), IFERROR(INDEX(_xlpm.f,_xlfn.XMATCH(TRUE,_xlpm.m,0)),"Other") )} -> Other
A23: Product Management Cloud Service | B23: {=_xlfn.LET( _xlpm.p,A23, _xlpm.k,Mapping!$A$2:$A$55, _xlpm.f,Mapping!$B$2:$B$55, _xlpm.m,_xlfn.MAP(_xlpm.k,_xlfn.LAMBDA(_xlpm.x,ISNUMBER(SEARCH(_xlpm.x,_xlpm.p)))), IFERROR(INDEX(_xlpm.f,_xlfn.XMATCH(TRUE,_xlpm.m,0)),"Other") )} -> Other
A24: Hyperion Financial Management Plus | B24: {=_xlfn.LET( _xlpm.p,A24, _xlpm.k,Mapping!$A$2:$A$55, _xlpm.f,Mapping!$B$2:$B$55, _xlpm.m,_xlfn.MAP(_xlpm.k,_xlfn.LAMBDA(_xlpm.x,ISNUMBER(SEARCH(_xlpm.x,_xlpm.p)))), IFERROR(INDEX(_xlpm.f,_xlfn.XMATCH(TRUE,_xlpm.m,0)),"Other") )} -> Hyperion
A25: OU - CLS - Cloud Unspecified CF | B25: {=_xlfn.LET( _xlpm.p,A25, _xlpm.k,Mapping!$A$2:$A$55, _xlpm.f,Mapping!$B$2:$B$55, _xlpm.m,_xlfn.MAP(_xlpm.k,_xlfn.LAMBDA(_xlpm.x,ISNUMBER(SEARCH(_xlpm.x,_xlpm.p)))), IFERROR(INDEX(_xlpm.f,_xlfn.XMATCH(TRUE,_xlpm.m,0)),"Other") )} -> Other
A26: Procurement | B26: {=_xlfn.LET( _xlpm.p,A26, _xlpm.k,Mapping!$A$2:$A$55, _xlpm.f,Mapping!$B$2:$B$55, _xlpm.m,_xlfn.MAP(_xlpm.k,_xlfn.LAMBDA(_xlpm.x,ISNUMBER(SEARCH(_xlpm.x,_xlpm.p)))), IFERROR(INDEX(_xlpm.f,_xlfn.XMATCH(TRUE,_xlpm.m,0)),"Other") )} -> ERP-Cloud
A27: Fusion Procurement for Self Service Cloud Service | B27: {=_xlfn.LET( _xlpm.p,A27, _xlpm.k,Mapping!$A$2:$A$55, _xlpm.f,Mapping!$B$2:$B$55, _xlpm.m,_xlfn.MAP(_xlpm.k,_xlfn.LAMBDA(_xlpm.x,ISNUMBER(SEARCH(_xlpm.x,_xlpm.p)))), IFERROR(INDEX(_xlpm.f,_xlfn.XMATCH(TRUE,_xlpm.m,0)),"Other") )} -> ERP-Cloud
A28: Fusion Enterprise Resource Planning for Self Service Cloud Service | B28: {=_xlfn.LET( _xlpm.p,A28, _xlpm.k,Mapping!$A$2:$A$55, _xlpm.f,Mapping!$B$2:$B$55, _xlpm.m,_xlfn.MAP(_xlpm.k,_xlfn.LAMBDA(_xlpm.x,ISNUMBER(SEARCH(_xlpm.x,_xlpm.p)))), IFERROR(INDEX(_xlpm.f,_xlfn.XMATCH(TRUE,_xlpm.m,0)),"Other") )} -> Other
... A415: AP 6350 | B415: {=_xlfn.LET( _xlpm.p,A415, _xlpm.k,Mapping!$A$2:$A$55, _xlpm.f,Mapping!$B$2:$B$55, _xlpm.m,_xlfn.MAP(_xlpm.k,_xlfn.LAMBDA(_xlpm.x,ISNUMBER(SEARCH(_xlpm.x,_xlpm.p)))), IFERROR(INDEX(_xlpm.f,_xlfn.XMATCH(TRUE,_xlpm.m,0)),"Other") )} -> TELCO-HW
B416: {=_xlfn.LET( _xlpm.p,A416, _xlpm.k,Mapping!$A$2:$A$55, _xlpm.f,Mapping!$B$2:$B$55, _xlpm.m,_xlfn.MAP(_xlpm.k,_xlfn.LAMBDA(_xlpm.x,ISNUMBER(SEARCH(_xlpm.x,_xlpm.p)))), IFERROR(INDEX(_xlpm.f,_xlfn.XMATCH(TRUE,_xlpm.m,0)),"Other") )} -> Other
B417: {=_xlfn.LET( _xlpm.p,A417, _xlpm.k,Mapping!$A$2:$A$55, _xlpm.f,Mapping!$B$2:$B$55, _xlpm.m,_xlfn.MAP(_xlpm.k,_xlfn.LAMBDA(_xlpm.x,ISNUMBER(SEARCH(_xlpm.x,_xlpm.p)))), IFERROR(INDEX(_xlpm.f,_xlfn.XMATCH(TRUE,_xlpm.m,0)),"Other") )} -> Other
B418: {=_xlfn.LET( _xlpm.p,A418, _xlpm.k,Mapping!$A$2:$A$55, _xlpm.f,Mapping!$B$2:$B$55, _xlpm.m,_xlfn.MAP(_xlpm.k,_xlfn.LAMBDA(_xlpm.x,ISNUMBER(SEARCH(_xlpm.x,_xlpm.p)))), IFERROR(INDEX(_xlpm.f,_xlfn.XMATCH(TRUE,_xlpm.m,0)),"Other") )} -> Other
B419: {=_xlfn.LET( _xlpm.p,A419, _xlpm.k,Mapping!$A$2:$A$55, _xlpm.f,Mapping!$B$2:$B$55, _xlpm.m,_xlfn.MAP(_xlpm.k,_xlfn.LAMBDA(_xlpm.x,ISNUMBER(SEARCH(_xlpm.x,_xlpm.p)))), IFERROR(INDEX(_xlpm.f,_xlfn.XMATCH(TRUE,_xlpm.m,0)),"Other") )} -> Other
B420: {=_xlfn.LET( _xlpm.p,A420, _xlpm.k,Mapping!$A$2:$A$55, _xlpm.f,Mapping!$B$2:$B$55, _xlpm.m,_xlfn.MAP(_xlpm.k,_xlfn.LAMBDA(_xlpm.x,ISNUMBER(SEARCH(_xlpm.x,_xlpm.p)))), IFERROR(INDEX(_xlpm.f,_xlfn.XMATCH(TRUE,_xlpm.m,0)),"Other") )} -> Other
B421: {=_xlfn.LET( _xlpm.p,A421, _xlpm.k,Mapping!$A$2:$A$55, _xlpm.f,Mapping!$B$2:$B$55, _xlpm.m,_xlfn.MAP(_xlpm.k,_xlfn.LAMBDA(_xlpm.x,ISNUMBER(SEARCH(_xlpm.x,_xlpm.p)))), IFERROR(INDEX(_xlpm.f,_xlfn.XMATCH(TRUE,_xlpm.m,0)),"Other") )} -> Other
B422: {=_xlfn.LET( _xlpm.p,A422, _xlpm.k,Mapping!$A$2:$A$55, _xlpm.f,Mapping!$B$2:$B$55, _xlpm.m,_xlfn.MAP(_xlpm.k,_xlfn.LAMBDA(_xlpm.x,ISNUMBER(SEARCH(_xlpm.x,_xlpm.p)))), IFERROR(INDEX(_xlpm.f,_xlfn.XMATCH(TRUE,_xlpm.m,0)),"Other") )} -> Other
B423: {=_xlfn.LET( _xlpm.p,A423, _xlpm.k,Mapping!$A$2:$A$55, _xlpm.f,Mapping!$B$2:$B$55, _xlpm.m,_xlfn.MAP(_xlpm.k,_xlfn.LAMBDA(_xlpm.x,ISNUMBER(SEARCH(_xlpm.x,_xlpm.p)))), IFERROR(INDEX(_xlpm.f,_xlfn.XMATCH(TRUE,_xlpm.m,0)),"Other") )} -> Other
B424: {=_xlfn.LET( _xlpm.p,A424, _xlpm.k,Mapping!$A$2:$A$55, _xlpm.f,Mapping!$B$2:$B$55, _xlpm.m,_xlfn.MAP(_xlpm.k,_xlfn.LAMBDA(_xlpm.x,ISNUMBER(SEARCH(_xlpm.x,_xlpm.p)))), IFERROR(INDEX(_xlpm.f,_xlfn.XMATCH(TRUE,_xlpm.m,0)),"Other") )} -> Other
B425: {=_xlfn.LET( _xlpm.p,A425, _xlpm.k,Mapping!$A$2:$A$55, _xlpm.f,Mapping!$B$2:$B$55, _xlpm.m,_xlfn.MAP(_xlpm.k,_xlfn.LAMBDA(_xlpm.x,ISNUMBER(SEARCH(_xlpm.x,_xlpm.p)))), IFERROR(INDEX(_xlpm.f,_xlfn.XMATCH(TRUE,_xlpm.m,0)),"Other") )} -> Other
B426: {=_xlfn.LET( _xlpm.p,A426, _xlpm.k,Mapping!$A$2:$A$55, _xlpm.f,Mapping!$B$2:$B$55, _xlpm.m,_xlfn.MAP(_xlpm.k,_xlfn.LAMBDA(_xlpm.x,ISNUMBER(SEARCH(_xlpm.x,_xlpm.p)))), IFERROR(INDEX(_xlpm.f,_xlfn.XMATCH(TRUE,_xlpm.m,0)),"Other") )} -> Other
...
